output/10:00.txt
VWAP at time: 10:00
Symbol  VWAP
--------------
UWN   2.4700
MFINL   25.6000
FXS   102.8700
PSB-W   22.0000
EQRR   41.8000
VCF   13.8000
BKK   14.9300
PAK   9.0100
BFRA   13.3300
CDR-B   24.8200
HE-U   26.4000
BXP-B   24.7000
ESGV   45.8500
TRTY   24.0000
DBEZ   28.2400
JPM-H   25.9900
STAG-C   25.6400
JPM-E   25.6300
USB-P   25.1000
DUKB   24.9200
FXO   29.6800
TIPZ   56.1800
TLH   132.9057
IDEV   51.9600
HTY   6.8710
TAT   1.2700
SAMA   9.6700
BPOPN   25.7100
HEWU   22.1800
CLIX   47.1600
ALGRU   10.3800
NNY   9.4100
ADILW   0.7500
LN   36.1497
NMI   10.5489
JHAA   10.2543
ENTX   4.0625
HAFC   22.3337
TWLVW   0.2290
ITM   47.6500
AC   41.1400
MYI   12.2800
WFC-W   25.3500
GRFS   18.6055
BTT   21.6700
JMU   0.8059
FXD   39.9899
NS-B   20.3000
ISMD   25.4349
DES   26.8682
INFU   3.7300
UAA   20.9514
CBL-E   12.9600
CWB   49.6127
EVI   36.1300
HPI   20.7900
HBANN   25.4100
PDN   29.2900
ATKR   22.1475
ARYAU   10.4800
GYB   20.8625
UDN   21.0300
USRT   49.7800
FTXG   18.8734
GBAB   22.3977
RWL   49.7900
SMTS   1.8400
MUH   13.6500
BKJ   13.3600
EDEN   59.0500
OCUL   3.7760
ZOM   0.9108
USAC   14.8970
GMFL   25.8300
DOL   44.8900
DOO   39.8800
MTDR   19.2157
INS   21.0158
AXS-D   23.4000
ESGRP   25.1508
AFSI-A   7.9988
CHRA   7.2704
QVAL   28.3400
EIV   11.7250
IHG   58.5840
WFC-T   25.7900
ICLN   9.2795
CVCY   19.7554
BANFP   26.4488
OUSA   31.0700
EWK   17.4800
ONCE   43.4341
PHI   25.0352
PFXF   18.7436
AVGR   0.3234
ROUS   29.8900
GLPI   36.7307
OSN   1.8500
ATMP   19.8767
CATC   75.5294
GLOP-C   22.9000
BAC-K   25.4500
PLYA   7.8565
BHK   12.8900
MUFG   5.3105
EQC-D   25.6500
IEIH   24.7300
BSGM   4.3001
IPG   22.5749
NEE-I   23.7100
IYC   193.0500
NGHCP   21.2500
BCRH   6.4600
PS   28.4320
DTW   23.8600
JLS   22.6057
LLL   195.5941
BRG-A   25.3200
WFC-P   23.4400
FTACW   0.7997
EXFO   3.2900
EGY   1.8633
WES   49.2762
STZ.B   169.4800
AVCO   5.5245
IRBO   22.3800
LPG   5.4579
ETON   6.1997
BWX   27.8258
HSBC-A   25.7850
CMU   4.5344
RILYI   24.9400
VKQ   11.7900
PFD   12.9443
PEI-D   18.0425
GLV   10.7500
MPVD   1.1700
ANIP   53.1436
PGF   18.0425
WPP   57.9700
MFDX   23.7000
SBI   8.6200
XPP   65.3008
HYXU   49.0600
MFT   13.1000
EDN   28.3100
NS-C   23.4600
CLNY-I   20.3400
ISG   25.5400
MSFT   104.7020
ALLY-A   26.0925
PEBK   25.7400
AUSE   51.3500
DDD   12.0743
BBT-G   23.9200
BBT-D   25.5100
SZNE   25.2300
NRCG+   0.9977
NTNX   49.9076
BAC-E   21.3400
PSB-Y   21.8500
UGP   15.1935
UZA   24.4929
TMCXW   0.4100
NETS   2.4000
FCT   11.7664
PHIOW   0.0250
JASNW   0.0080
WHLRW   0.0100
LFACW   0.3500
ESXB   7.3914
BRACW   0.2400
AMBCW   9.2500
TDW+   0.5800
OXBRW   0.0121
EFC   16.3193
PGHY   23.0713
BFZ   12.3900
CCBG   23.4618
RJI   5.2278
LXFR   19.8790
COMG   21.2000
ALFA   45.2400
DHDG   21.9600
BSJP   23.4800
SMIN   35.7474
BRACR   0.3225
PML   13.4866
USDP   11.2440
SMDD   10.1500
WCG   274.9206
JPUS   69.2700
HA   29.8291
IMTE   6.2853
USOD   7.3100
VNLA   49.3418
TFI   48.3026
BSCP   19.9950
JPGE   57.7400
SPXL   38.5371
EARN   11.5199
PJH   24.9800
ORG   26.2076
SF-A   25.4725
OHAI   1.1600
NTX   12.7600
C-L*   25.4100
BBF   12.7800
SAL   39.2074
MVF   8.7400
PSA-E   22.1700
MQT   11.8550
JCAP-B   23.5000
APO-A   24.5600
HYB   8.1567
MER-K   25.7600
HSON   1.4300
CAAP   6.9992
SGG   43.5500
LEO   7.6333
ITEQ   34.1450
SFIX   23.2467
GOAT   25.8500
FAN   12.5550
THQ   17.3324
SRT   6.8056
TSRI   5.5800
TAC   5.3319
PFFL   23.5978
JPN   26.1301
NUE   59.8631
MNI   6.2167
SLVP   8.7646
DMAC   3.8438
MHE   11.8900
ETP-D   24.6072
DTLA-   21.0000
ETW   9.6900
VIVO   16.0379
GIS   43.7276
ROBO   35.6455
AGRO   7.1616
SLMBP   64.4500
AGGY   48.6217
RVLT   0.6699
WRB-D   24.4950
PFO   11.2200
INPX   2.1935
HTGM   2.0907
INT   24.4525
BDC-B   71.8600
MTUM   104.5396
ACWF   28.0300
FLY   11.0351
PWC   92.4500
PSK   41.6964
ETR   87.0609
FIF   14.9360
JMT   22.2200
C-J   26.6500
DRW   30.6475
GLO   9.0305
FEYE   17.4243
MGF   4.4700
PRS   24.8914
AWX   2.8000
IFN   20.1200
EXD   9.0802
PSA-V   23.8100
ERX   19.5791
AXDX   18.2413
AMX   15.7130
TCP   32.6854
PCG-G   15.7815
PMX   11.6300
FFA   14.0471
OLP   27.5364
XPH   39.2586
OCSLL   24.5239
SJB   22.6182
BYSI   18.3734
FDBC   60.6900
NRIM   32.4274
MFSF   28.0142
CHIQ   14.4725
IGRO   52.5300
XHS   68.4600
FDD   12.6392
FINU   71.7333
BIZD   15.7200
PUK   39.1705
PFL   11.2900
NFLX   334.0097
FELP   3.3500
FXP   65.8160
FRA   12.5025
ONEQ   277.6048
WELL-I   67.5977
TRIB   2.4990
RCS   9.8225
AMH-E   23.8131
PMD   18.3654
AFIF   9.9400
SQNS   1.0950
CVM   2.7295
CO   6.2300
NSL   5.7040
OPHC   3.5227
DBB   16.2591
FTXO   25.5679
CIL   36.6500
EDOG   22.4114
BDX   242.7777
DHX   2.0560
DDE   2.6900
RNDV   20.5100
STRT   34.7517
WPG-H   15.7500
BNS   56.4081
RIF   17.5190
AWF   11.2698
PCTY   67.8605
GHYG   47.7178
VFMF   72.4100
JMF   9.2102
TOL   35.0837
PCYG   7.8722
MRC   15.4323
WBIY   23.8500
VMO   11.7000
NIM   9.8631
GHG   11.0094
GGO   15.0000
WTIU   13.3698
IAK   60.9617
GMLPP   24.9469
MOBL   4.7851
EDV   112.5013
IBDR   23.5500
STON   2.1567
C-K   26.6600
JPMV   65.3200
BPTH   1.9797
CNXM   17.2423
GIM   6.3662
DELT   1.1400
WDIV   65.3475
VRCA   11.8937
ESBA   15.2478
RYF   39.7164
CAI-A   24.8900
SG   14.5000
BRS   3.6811
CXH   9.4500
RVP   0.6895
MCA   12.9900
ESND   12.8081
CCB   15.3475
NEAR   50.0800
NVCR   47.7035
NEBUW   0.8500
GNR   44.5105
XBUY   24.8100
MTEM   4.3469
EMD   13.4100
TALO   18.9479
PRCP   8.0000
USDU   26.9100
ECON   21.9820
PPR   4.7100
GLTR   64.8450
GOEX   21.4500
SHM   48.2200
IHE   143.5250
HLTH   0.4443
IBDL   25.1200
QTS   41.4655
FORTY   39.0400
SRV   9.8800
AMOV   15.6250
NMFC   13.8584
BAC-B   26.0300
BXMX   12.8283
FGD   23.2949
BGT   12.1200
VSAT   61.1661
VISI   3.7000
IYW   168.9936
VLUE   78.3282
MGV   74.9293
RYE   49.3099
DLTH   23.1015
VDC   135.1952
DDIV   22.7400
COWZ   28.4057
BSCO   20.2460
MIK   14.0429
CRBN   110.5300
TBLTW   0.4957
PMO   11.8000
FREL   24.7458
CRCM   23.1944
KMF   11.2774
OFG-A   24.4200
HFRO   13.8632
SPDW   28.2083
SHO-E   25.5000
MUA   13.8834
MGC   91.6120
TEI   10.3432
DUSA   21.7000
CTBB   20.1646
MFL   12.7633
OMAD   10.0800
DSM   7.3520
EPAY   49.4319
NKX   13.2698
BCV   20.8343
IAT   45.3905
NBY   2.1449
GS-J   25.1400
PTIE   1.1643
NMCI   2.8583
DWX   36.7827
HBK   13.6800
SMTX   5.3243
EBTC   31.1100
SWK   122.9732
NODK   15.0200
HIVE   3.7608
PFBI   14.2526
CFG-D   25.4469
HYT   9.8960
IWD   117.8526
DKL   30.2165
TOLZ   41.4200
USB-H   19.5233
CVRS   1.1900
BFK   12.9025
HYHG   65.1898
MTNB   0.9238
FAT   5.3700
AWP   5.6725
FTD   2.4555
SAMAU   10.0000
IWL   61.3800
VAW   119.3349
FLGE   216.0000
INDL   58.0757
WFC-V   25.8065
TMQ   2.0820
QUS   76.9400
CORE   27.9442
JOBS   66.3797
MBCN   42.9500
KBR   17.0177
RNP   19.3475
FM   28.2400
YANG   52.7388
QAT   19.1368
BXG   12.7783
NJV   12.8600
HIMX   3.8986
RA   20.7974
MED   123.0323
MQY   13.6396
TLI   9.3200
ISR   0.4174
LMFAW   0.0338
NOVT   66.4053
FPXI   32.8700
PHUNW   0.5341
MDLY   4.4547
FNDA   35.9075
IEF   104.0436
FTF   9.4486
FNDB   35.8000
PFM   25.7800
IAI   60.3341
SPVU   33.4000
MAV   10.9340
VGI   11.8500
XTN   59.2692
IYT   178.5636
INSW   17.5107
TLC   6.4273
MINT   101.3598
PMF   13.2529
FGP   1.0760
VNO-L   23.4386
VOT   130.4277
BW   0.4956
DVYE   41.0349
BOND   103.5014
WWD   85.9199
RENN   1.6500
ROAD   11.9064
SQBG   1.0363
SKF   20.6200
TME   15.2096
RBC   75.1097
EFAS   16.1000
FPH   7.5316
AMAG   15.3709
HQL   17.0593
GLP   19.0556
VXZB   20.2204
VRP   23.9400
CHAU   16.8400
WKHS   0.8786
IBML   25.2700
TDJ   25.2350
TSLF   15.3467
LIN   162.0676
TDACU   10.2461
MH-D   5.2998
SAGE   132.0155
DTD   89.5100
MTL-   0.6960
XMLV   47.0102
GPX   14.9762
SMDV   56.6895
HIO   4.7008
UBA   20.8871
QRVO   64.6206
TECH   164.9947
NRGX   20.2583
NTGR   38.1193
CHAP   8.0096
AVD   17.2429
FTAI   14.6548
ASH   76.3935
GTES   14.5766
CMP   51.2154
WRB-C   25.0733
DUG   41.0491
FXY   87.0640
FENG   3.5900
PJP   64.6000
UYG   38.1100
PEI   7.6176
PBT   6.6202
MVBF   16.5002
BBN   21.7349
UZB   24.9850
EET   71.3700
BCX   7.8973
EFSC   44.8060
