output/11:00.txt
VWAP at time: 11:00
Symbol  VWAP
--------------
USEQ   26.1400
CIZN   21.3219
TANNI   25.2500
JHX   10.8900
THST   2.1400
CSPI   10.0000
BLES   26.6000
PCEF   21.4900
PNC-Q   24.8800
LTL   34.8900
TAWK   24.2400
RWGV   50.7700
RWLS   51.1800
PFIN   7.8200
CEY   24.5417
MMTM   114.7800
PWS   24.0000
AVH   4.6200
RF-B   26.4600
FRAK   12.5000
IMTB   48.4900
PCG-C   16.6400
NC   33.9655
LTPZ   62.5700
EHT   9.4800
FTAG   23.6800
GTO   50.6800
SSW-H   23.2500
MET-A   23.0200
MAGA   25.5000
PIHPP   22.1000
NNVC   0.3100
SIJ   16.4000
IQDY   23.6200
DOD   23.8000
SSG   17.6000
SHYD   24.3500
DEF   46.8600
PZN   8.3367
GGZ   11.1400
PPX   25.1700
DSS   0.9841
IAF   5.1800
USHY   47.6400
CMSC   25.5052
ZF   9.1500
GHII   25.6000
NEWTI   25.5928
TVE   24.9600
DNN   0.5240
HEWP   20.9500
NOM   12.3153
GS-D   19.1900
GIG^   0.2400
MHH   7.9900
DLNG-A   20.8500
SNV-D   25.1100
ABR-C   25.6400
ONEO   67.8200
NUAG   23.3700
TRT   2.9500
CLTL   105.4600
JPME   62.0600
WFHY   49.4000
EWO   19.9200
PDT   15.5823
CNP-B   52.7600
MITT-B   25.3800
VJET   2.0800
NTIC   30.8287
PCQ   16.9500
INF   11.6112
TCBIL   25.3000
ALD   44.0657
SHAG   49.1200
DTF   12.9520
GLADD   25.1012
AFGH   26.1000
SRC-A   22.2200
PPT   4.9830
EYESW   0.3300
NORW   12.2600
SDD   14.7600
CCM   3.1301
SRG-A   23.1833
INTF   25.7593
GVAL   22.8211
ELJ   25.3300
DCF   8.3400
TNP-E   21.7700
NOVN   1.3765
BYM   13.0100
DBGR   24.7100
PT   11.0000
ISCF   27.8400
DSWL   3.0300
ALYA   2.8392
THM   0.6200
JHMD   27.2306
GBR   1.7052
MFA-B   24.7700
GDO   15.9800
ALL-A   25.4967
PULS   50.0750
TDW+A   2.2200
UST   55.4400
OGIG   21.2550
TLTE   51.9614
PMT-B   24.7000
PYN   9.6100
HHS   3.0686
DBE   14.0000
AHT-D   24.9200
MSUS   22.8700
SRLN   45.8844
VIDI   24.5000
HCXZ   24.2420
GMO   0.2288
PLND   17.1400
BOUT   18.8781
FMN   13.0600
FLAG   39.4000
CII   15.1054
TZACU   10.1100
UBP   16.9746
ZMLP   13.5800
SOR   34.7302
DCP-C   23.7235
BWG   11.0400
YYY   17.2375
TCBIP   25.2000
BAC-C   26.3413
ISF   25.6700
ALL-B   25.1500
VER-F   25.1852
BHR-B   18.0050
MH-A   6.5500
UNMA   25.0011
HTD   22.5800
TKKSR   0.2600
TKKSW   0.1613
EVM   10.2700
BSD   12.6200
TGP-A   24.8728
JHB   9.6883
FTSD   94.5300
ALO   0.8075
JPGB   48.5000
TYNS   28.2300
PTNQ   32.7300
ASFI   4.2550
FDRR   30.2450
PEO   16.0852
BOSS   18.1300
PBI-B   24.2400
LVHB   31.1900
SMMV   30.8000
FRN   12.8300
DDG   24.8500
PUTW   26.0000
EUSA   54.2481
GAMR   41.9394
QEFA   59.5400
RHS   120.7686
SPVM   26.6200
CLRG   23.3123
MIY   12.8203
MHNC   17.7568
CUBI-E   25.8300
HDGE   7.5900
NAZ   12.1407
SLTB   25.3445
GNL-A   24.5300
KLDW   31.1000
UWN   2.4700
UQM   1.6496
MFINL   25.6000
FXS   102.8700
PSB-W   22.0000
EQRR   41.8000
VCF   13.8000
BKK   14.9300
CLNY-G   21.7500
PAK   9.0100
BFRA   13.3300
CDR-B   24.4563
HE-U   26.4000
BXP-B   24.7842
ESGV   45.9161
TRTY   24.0000
DBEZ   28.2400
JPM-H   25.9900
STAG-C   25.6400
JPM-E   25.6363
USB-P   25.1165
DUKB   24.9200
FXO   29.7375
TIPZ   56.1887
TLH   132.8922
IDEV   51.9611
HTY   6.8710
TAT   1.2700
SAMA   9.6700
BPOPN   25.7100
HEWU   22.1800
CLIX   47.1600
ALGRU   10.3800
NNY   9.4100
ADILW   0.7499
LN   36.2445
NMI   10.5494
JHAA   10.2543
ENTX   4.0542
HAFC   22.3310
TWLVW   0.2290
ITM   47.6300
AC   41.2941
MYI   12.2792
WFC-W   25.3500
GRFS   18.6097
BTT   21.6977
JMU   0.8051
FXD   39.9899
NS-B   20.3000
ISMD   25.4349
DES   26.9303
INFU   3.7323
UAA   20.9432
CBL-E   12.9853
CWB   49.6287
EVI   36.0837
HPI   20.7900
HBANN   25.4100
PDN   29.2900
ATKR   22.1225
ARYAU   10.4800
GYB   20.8625
UDN   21.0300
USRT   49.7309
FTXG   18.8734
GBAB   22.4369
RWL   49.7900
SMTS   1.8400
MUH   13.6500
BKJ   13.3600
EDEN   59.0500
OCUL   3.7567
ZOM   0.9108
USAC   14.9226
GMFL   25.8300
DOL   44.8900
DOO   39.9000
MTDR   19.2481
INS   21.0069
AXS-D   23.4000
ESGRP   25.1564
AFSI-A   8.0013
CHRA   7.3018
QVAL   28.3400
EIV   11.7167
IHG   58.5311
WFC-T   25.7900
ICLN   9.2795
CVCY   19.7554
BANFP   26.4488
OUSA   31.0700
EWK   17.4800
ONCE   43.4599
PHI   24.9237
PFXF   18.7913
AVGR   0.3238
ROUS   29.8900
GLPI   36.7642
OSN   1.8500
ATMP   19.9570
CATC   75.5294
GLOP-C   22.6788
BAC-K   25.4500
PLYA   7.8674
BHK   12.8900
MUFG   5.3170
EQC-D   25.6500
IEIH   24.7300
BSGM   4.3019
IPG   22.6315
NEE-I   23.7100
IYC   193.2254
NGHCP   21.2776
BCRH   6.4385
PS   28.3482
DTW   23.8748
JLS   22.6175
LLL   196.3376
BRG-A   25.3400
WFC-P   23.4400
FTACW   0.7998
EXFO   3.2900
EGY   1.8564
WES   49.5598
STZ.B   169.4800
AVCO   5.5177
IRBO   22.3865
LPG   5.4536
ETON   6.1997
BWX   27.8294
HSBC-A   25.7850
CMU   4.5404
RILYI   24.9400
VKQ   11.7775
PFD   12.9255
PEI-D   18.0425
GLV   10.7047
MPVD   1.1700
ANIP   53.2658
PGF   18.0506
WPP   57.8041
MFDX   23.7150
SBI   8.6002
XPP   65.3008
HYXU   49.0600
MFT   13.0960
EDN   28.4354
NS-C   23.4600
CLNY-I   20.3400
ISG   25.5448
MSFT   104.7795
ALLY-A   26.0925
PEBK   25.6357
AUSE   51.3500
DDD   12.0655
BBT-G   23.9500
BBT-D   25.5767
SZNE   25.2300
NRCG+   0.9977
NTNX   49.8623
BAC-E   21.3350
PSB-Y   21.8569
UGP   15.1538
UZA   24.4929
TMCXW   0.4100
NETS   2.4000
FCT   11.7668
PHIOW   0.0250
JASNW   0.0080
WHLRW   0.0100
LFACW   0.3500
ESXB   7.3914
BRACW   0.2400
AMBCW   9.2500
TDW+   0.5800
OXBRW   0.0121
EFC   16.3387
PGHY   23.0713
BFZ   12.3900
CCBG   23.5046
RJI   5.2340
LXFR   19.8694
COMG   21.2000
ALFA   45.2950
DHDG   21.9600
BSJP   23.4800
SMIN   35.7474
BRACR   0.3225
PML   13.4917
USDP   11.2600
SMDD   10.1500
WCG   274.9934
JPUS   69.3164
HA   29.9320
IMTE   6.3220
USOD   7.1140
VNLA   49.3412
TFI   48.2788
BSCP   19.9883
JPGE   57.7400
SPXL   38.5806
EARN   11.5423
PJH   25.0250
ORG   26.2076
SF-A   25.4913
OHAI   1.1600
NTX   12.7530
C-L*   25.4100
BBF   12.7800
SAL   39.2074
MVF   8.7400
PSA-E   22.1700
MQT   11.8529
JCAP-B   23.5000
APO-A   24.5600
HYB   8.1604
MER-K   25.7840
HSON   1.4300
CAAP   6.9992
SGG   43.5500
LEO   7.6325
ITEQ   34.1450
SFIX   23.2415
GOAT   25.8500
FAN   12.5633
THQ   17.3324
SRT   6.8287
TSRI   5.5800
TAC   5.3356
PFFL   23.5978
JPN   26.1301
NUE   59.8424
MNI   6.1007
SLVP   8.7646
DMAC   3.8438
MHE   11.8900
ETP-D   24.6187
DTLA-   21.0000
ETW   9.6950
VIVO   16.0398
GIS   43.7680
ROBO   35.7119
AGRO   7.1963
SLMBP   65.3102
AGGY   48.6187
RVLT   0.6416
WRB-D   24.4950
PFO   11.2200
INPX   2.1919
HTGM   2.1174
INT   24.4976
BDC-B   72.2112
MTUM   104.6336
ACWF   28.0300
FLY   11.0922
PWC   92.4500
PSK   41.6964
ETR   87.1166
FIF   14.9481
JMT   22.2200
C-J   26.7130
DRW   30.7059
GLO   9.0414
FEYE   17.4150
MGF   4.4700
PRS   24.8844
AWX   2.7774
IFN   20.1132
EXD   9.0802
PSA-V   23.8100
ERX   19.6400
AXDX   18.2741
AMX   15.7017
TCP   32.7689
PCG-G   15.7815
PMX   11.6300
FFA   14.0538
OLP   27.5233
XPH   39.2698
OCSLL   24.5128
SJB   22.6182
BYSI   18.3609
FDBC   60.6900
NRIM   32.4274
MFSF   28.0159
CHIQ   14.4725
IGRO   52.5300
XHS   68.4600
FDD   12.6407
FINU   71.7568
BIZD   15.7952
PUK   39.1443
PFL   11.2900
PRTH   6.1500
NFLX   333.6640
FELP   3.3500
FXP   65.8298
FRA   12.5043
ONEQ   277.6310
WELL-I   67.5991
TRIB   2.4990
RCS   9.8225
AMH-E   23.8166
PMD   18.3665
AFIF   9.9400
SQNS   1.0994
CVM   2.7642
CO   6.1712
NSL   5.7163
OPHC   3.5227
DBB   16.2588
FTXO   25.5691
CIL   36.6500
EDOG   22.4114
BDX   242.8900
DHX   2.0560
DDE   2.6900
RNDV   20.5100
STRT   34.7517
WPG-H   15.7500
BNS   56.4211
RIF   17.5190
AWF   11.2755
PCTY   67.9814
GHYG   47.7178
VFMF   72.4100
JMF   9.2490
TOL   35.0659
PCYG   7.9066
MRC   15.4679
WBIY   23.8500
VMO   11.6965
NIM   9.8537
GHG   11.0142
GGO   15.0000
WTIU   13.8324
IAK   60.9617
GMLPP   24.9761
MOBL   4.7670
EDV   112.5060
IBDR   23.5500
STON   2.1410
C-K   26.7116
JPMV   65.3200
BPTH   2.0355
CNXM   17.2973
GIM   6.3700
DELT   1.1400
WDIV   65.3475
VRCA   11.9194
ESBA   15.2478
RYF   39.7778
CAI-A   24.8900
SG   14.4105
BRS   3.6746
CXH   9.4500
RVP   0.6895
MCA   12.9817
ESND   12.8080
CCB   15.3475
NEAR   50.0800
NVCR   47.2895
NEBUW   0.8500
GNR   44.5421
XBUY   24.8550
MTEM   4.3596
EMD   13.4258
TALO   19.0233
PRCP   8.0000
USDU   26.9100
ECON   21.9820
